<?xml version="1.0" ?>
<!-- =================================================================================== -->
<!-- |    This document was autogenerated by xacro from balance.xacro                  | -->
<!-- |    EDITING THIS FILE BY HAND IS NOT RECOMMENDED                                 | -->
<!-- =================================================================================== -->
<robot name="balance">

  <material name="blue">
    <color rgba="0 0 0.8 1"/>
  </material>
  <material name="white">
    <color rgba="1 1 1 1"/>
  </material>
  <link name="base_link">
    <visual>
      <geometry>
        <box size="0.42 0.36 0.15"/>
      </geometry>
      <material name="blue"/>
      <origin rpy="0 0 0" xyz="0 0 0"/>
    </visual>
    <collision>
      <geometry>
        <box size="0.42 0.36 0.15"/>
      </geometry>
    </collision>
    <inertial>
      <mass value="5.55"/>
      <inertia ixx="0.09199124999999998" ixy="0.0" ixz="0.0" iyy="0.09199124999999998" iyz="0.0" izz="0.09199124999999998"/>
    </inertial>
  </link>
  <link name="right_wheel">
    <visual>
      <geometry>
        <cylinder length="0.06" radius="0.1"/>
      </geometry>
      <material name="white"/>
      <origin rpy="0 0 0" xyz="0 0 0"/>
    </visual>
    <collision>
      <geometry>
        <cylinder length="0.06" radius="0.1"/>
      </geometry>
    </collision>
    <inertial>
      <mass value="0.98"/>
      <inertia ixx="0.0027440000000000003" ixy="0.0" ixz="0.0" iyy="0.0027440000000000003" iyz="0.0" izz="0.004900000000000001"/>
    </inertial>
  </link>
  <joint name="right_joint" type="continuous">
    <origin rpy="0 -1.57075 0" xyz="0.24 0 -0.1"/>
    <axis xyz="0 0 1"/>
    <parent link="base_link"/>
    <child link="right_wheel"/>
  </joint>
  <link name="left_wheel">
    <visual>
      <geometry>
        <cylinder length="0.06" radius="0.1"/>
      </geometry>
      <material name="white"/>
      <origin rpy="0 0 0" xyz="0 0 0"/>
    </visual>
    <collision>
      <geometry>
        <cylinder length="0.06" radius="0.1"/>
      </geometry>
    </collision>
    <inertial>
      <mass value="0.98"/>
      <inertia ixx="0.0027440000000000003" ixy="0.0" ixz="0.0" iyy="0.0027440000000000003" iyz="0.0" izz="0.004900000000000001"/>
    </inertial>
  </link>
  <joint name="left_joint" type="continuous">
    <origin rpy="0 -1.57075 0" xyz="-0.24 0 -0.1"/>
    <axis xyz="0 0 1"/>
    <parent link="base_link"/>
    <child link="left_wheel"/>
  </joint>
</robot>
